`resolve` и `reject` - это функции обратного вызова (callback) в `Promise`-объектах JavaScript, которые управляют результатом асинхронной операции, завершившейся успешно или с ошибкой.

Если операция завершается с ошибкой, мы вызываем функцию `reject()` и передаем ей объект ошибки в качестве параметра. Например:

`const promise = new Promise((resolve, reject) => { 
	`setTimeout(() => {    
		` const error = new Error('Something went wrong!');   
		`  reject(error);   }, 1000); }); 
		`promise.catch(error => {  
		` console.error(error); // "Error: Something went wrong!" });`

Здесь мы создаем `Promise`-объект, который возвращает объект ошибки. Внутри функции-конструктора `Promise` мы вызываем функцию `reject()` и передаем ей этот объект ошибки в качестве параметра. После этого `Promise` переходит в состояние `rejected`, и в метод `catch()` передается объект ошибки, который мы выводим на консоль.


[[promise]]

