Метод `catch()` является частью API Promise в JavaScript. Он позволяет назначить обработчик ошибки, который будет вызван, когда Promise перейдет в состояние "rejected" (выполнен с ошибкой).

Синтаксис метода `catch()` выглядит следующим образом:

`promise.catch(onRejected);`

-   `onRejected` - функция-обработчик, которая будет вызвана, если Promise перейдет в состояние "rejected".

Параметр является необязательным. Если не передать его, то метод `catch()` вернет Promise со значением, которое было передано в исходном Promise.

Вот пример использования метода `catch()`:

javascriptCopy code

`const promise = new Promise((resolve, reject) => {  
	`setTimeout(() => {     
		`reject(new Error("Data could not be fetched."));  
`` }, 1000); 
``});  
`promise.catch((error) => {   console.log(error); });`

В этом примере мы создаем `Promise` и задаем ему функцию-обработчик, которая вызывает метод `reject()`, чтобы выполнить Promise с ошибкой. Затем мы вызываем метод `catch()` на этом Promise и передаем ему функцию-обработчик, которая будет вызвана, когда Promise перейдет в состояние "rejected". Эта функция просто выводит сообщение об ошибке на консоль.

Метод `catch()` также возвращает новый Promise, который может быть использован для обработки ошибок в цепочке обработки асинхронных операций.

[[promise]]